# TDD Collection Error Debug Report

## Summary

The TDD validation flow for collection errors is functioning correctly at the data collection and context loading levels, but failing due to incorrect file categorization by the LLM.

## Findings

### ✅ Working Components

1. **Pytest Plugin Collection Error Capture**
   - Collection errors ARE being captured correctly
   - `collection_errors` array contains proper error details
   - Test results show `status: "failed"` and `errors: 1`

2. **TDD Context Loading**  
   - FileStorage correctly loads test results from the specified data directory
   - TDD context includes all necessary data: test_results, collection_errors, etc.
   - `has_failing_tests` logic correctly returns `True` when collection errors exist

3. **Heuristic Logic**
   - The TDDAnalysisProcessor has correct logic to detect failing tests:
     ```python
     has_failing_tests = bool(
         test_results and (
             test_results.get("failures") or
             test_results.get("errors", 0) > 0 or
             test_results.get("collection_errors")  # ✅ This works
         )
     )
     ```

### ❌ Root Cause: File Categorization Issues

The `FileCategorizationProcessor` is incorrectly classifying simple Python implementation files:

- Simple `hello.py` with `def main(): return "Hello, World!"` was classified as:
  - "user guide or reference manual" (first test run)  
  - "C++ source code" (second test run)

### Impact on TDD Flow

Because files are not categorized as "implementation", they bypass the heuristic check:

```python
# TDDAnalysisProcessor logic
if category not in ["implementation", "test"]:
    # Skips TDD validation entirely - WRONG for implementation files
    yield ProcessorPart(json.dumps({"approved": True, "reason": f"TDD validation not required for {category} files."}))
    return

# This heuristic check is never reached:
if category == "implementation" and not has_failing_tests:
    yield ProcessorPart(json.dumps({"approved": False, "reason": "TDD: Implementation change without a failing test."}))
    return
```

## Test Results Analysis

### Debug Script: `debug_collection_detailed.py`
- ✅ Collection error properly captured in test.json
- ✅ pytest plugin working correctly
- ✅ Test status correctly set to "failed"

### Debug Script: `debug_tdd_context.py`  
- ✅ TDD context loading working correctly
- ✅ `has_failing_tests` returns `True` as expected
- ❌ Validation still fails due to file categorization

### Debug Script: `debug_file_categorization.py`
- ❌ Simple Python implementation file misclassified
- ❌ LLM making incorrect content analysis decisions

## Recommendations

1. **Fix File Categorization Logic**
   - Review FileCategorizationProcessor prompts
   - Add fallback logic for simple Python files (*.py extension)
   - Consider file extension-based categorization as backup

2. **Add Defensive Logic**
   - If file has .py extension and contains `def` keywords, default to "implementation"
   - Add logging to track categorization decisions for debugging

3. **Test Coverage**
   - Add specific tests for file categorization edge cases
   - Test simple implementation files with various content types

## Files Analyzed

- `/cc_validator/tdd_pipeline.py` - TDD analysis logic ✅
- `/cc_validator/pytest_plugin.py` - Collection error capture ✅  
- `/cc_validator/file_storage.py` - Context loading ✅
- `/cc_validator/streaming_processors.py` - File categorization ❌

The collection error flow itself is working perfectly - the issue is in the file categorization step that precedes the TDD analysis.